<?xml version="1.0"?>
<robot name="gebot" xmlns:xacro="http://www.ros.org/wiki/xacro">
    
    <xacro:property name="base_width" value="0.8"/>
    <xacro:property name="base_length" value="1.4"/>
    <xacro:property name="base_height" value="0.15"/>

    <xacro:property name="wheel_radius" value="0.15"/>
    <xacro:property name="wheel_width" value="0.1"/>
    <xacro:property name="wheel_ygap" value="0.0"/>
    <xacro:property name="wheel_zoff" value="0.075"/>
    <xacro:property name="wheel_xoff" value="0.5"/>

    <!-- Defination of some commonly used intertial properties  -->
    <xacro:macro name="box_inertia" params="m w h d">
        <inertial>
            <origin xyz="0 0 0" rpy="${pi/2} 0 ${pi/2}"/>
            <mass value="${m}"/>
            <inertia ixx="${(m/12) * (h*h + d*d)}" ixy="0.0" ixz="0.0" iyy="${(m/12) * (w*w + d*d)}" iyz="0.0" izz="${(m/12) * (w*w + h*h)}"/>
        </inertial>
    </xacro:macro>

    <xacro:macro name="cylinder_inertia" params="m r h">
        <inertial>
            <origin xyz="0 0 0" rpy="${pi/2} 0 0" />
            <mass value="${m}"/>
            <inertia ixx="${(m/12) * (3*r*r + h*h)}" ixy = "0" ixz = "0" iyy="${(m/12) * (3*r*r + h*h)}" iyz = "0" izz="${(m/2) * (r*r)}"/>
        </inertial>
    </xacro:macro>

    <!-- Material -->
    <material name="black">
        <color rgba="0.0 0.0 0.0 1.0"/>
    </material>
    <material name="white">
        <color rgba="1.0 1.0 1.0 1.0"/>
    </material>
    <material name="wheel">
        <color rgba="0.15 0.15 0.15 1.0"/>
    </material>
    <material name="myblue">
        <color rgba="0.0 0.0 0.5 1.0"/>
    </material>
    <material name="base">
        <color rgba="0.2 0.05 0.05 1.0"/>
    </material>
    <material name="lidar">
        <color rgba="0.8 0.0 0.0 1.0"/>
    </material>

    <!-- Robot Base -->
    <link name="base_link"/>

    <link name="base_chassis">
        <collision>
            <origin xyz="0.0 0.0 0.0" rpy="0.0 0.0 0.0"/>
            <geometry>
                <box size="${base_length} ${base_width} ${base_height}"/>
            </geometry>
        </collision>
        <visual>
            <origin xyz="0.0 0.0 0.0" rpy="0.0 0.0 0.0"/>
            <geometry>
                <box size="${base_length} ${base_width} ${base_height}"/>
            </geometry>
            <material name="base"/>
        </visual>

        <xacro:box_inertia m="2" w="${base_width}" d="${base_length}" h="${base_height}"/>
    </link>

    <joint name="base_link_joint" type="fixed">
        <origin xyz="0.5 0.0 0.225" rpy="0.0 0.0 0.0"/>
        <parent link="base_link"/>
        <child link="base_chassis"/>
    </joint>

    <!-- Wheels -->
    <xacro:macro name="wheel" params="prefix x_reflect y_reflect">
        <link name="${prefix}">
            <collision>
                <!--origin xyz="0 0 0" rpy="${pi/2} 0 0"/-->
                <geometry>
                    <cylinder radius="${wheel_radius}" length="${wheel_width}"/>
                </geometry>
            </collision>
            <visual>
                <!--origin xyz="0 0 0" rpy="${pi/2} 0 0"/-->
                <geometry>
                    <cylinder radius="${wheel_radius}" length="${wheel_width}"/>
                </geometry>
                <material name="wheel"/>
            </visual>
            
            <xacro:cylinder_inertia m="1" r="${wheel_radius}" h="${wheel_width}"/>
        </link>

        <joint name="${prefix}_joint" type="continuous">
            <origin xyz="${x_reflect*wheel_xoff} ${y_reflect*(base_width/2+wheel_ygap)} ${-wheel_zoff}" rpy="${-pi/2} 0 0"/>
            <parent link="base_chassis"/>
            <child link="${prefix}"/>
            <axis xyz="0 0 1"/>
            <dynamics damping="0.2"/>
        </joint>
    </xacro:macro>

    <xacro:wheel prefix="right_wheel" x_reflect="-1" y_reflect="-1" />
    <xacro:wheel prefix="left_wheel" x_reflect="-1" y_reflect="1" />

    <!-- Front Wheel and Joint-->
    <link name="front_wheel">
        <visual>
            <!--origin xyz="0 0 0" rpy="${pi/2} 0 0"/-->
            <geometry>
                <cylinder radius="${wheel_radius}" length="${wheel_width}"/>
            </geometry>
            <material name="wheel"/>
        </visual>
        <collision>
            <!--origin xyz="0 0 0" rpy="${pi/2} 0 0"/-->
            <geometry>
                <cylinder radius="${wheel_radius}" length="${wheel_width}"/>
            </geometry>
        </collision>
        <xacro:cylinder_inertia m="5" r="${wheel_radius}" h="${wheel_width}"/>
    </link>

    <!--<joint name="front_wheel_joint" type="continuous">
        <axis xyz="0 1 0"/>
        <parent link="base_link"/>
        <child link="front_wheel"/>
        <origin xyz="0.5 0.0 -0.125"/>
    </joint>-->

    <!-- Steering Links and Joints-->
    <link name="steering_link">
        <visual>
            <origin xyz="0.0 0.0 0.0" rpy="0.0 0.0 0.0"/>
            <geometry>
                <cylinder radius="0.02"  length="0.8"/>
            </geometry>
            <material name="white"/>
        </visual>

        <collision>
            <origin xyz="0.0 0.0 0.0" rpy="0.0 0.0 0.0"/>
            <geometry>
                <cylinder radius="0.02"  length="0.8"/>
            </geometry>
        </collision>

        <xacro:cylinder_inertia m="0.01" r="0.02" h="0.8"/>
    </link>

    <joint name="front_steering_joint" type="revolute">
        <axis xyz="0 0 1"/>
        <limit effort="1000.0" lower="-1.4" upper="1.4" velocity="0.5"/>
        <parent link="base_chassis"/>
        <child link="steering_link"/>
        <origin xyz="0.6 0.05 0.3"/>
    </joint>

    <link name="connection">
        <visual>
            <origin xyz="0.0 0.0 0.0" rpy="${pi/2} 0.0 0.0"/>
            <geometry>
                <cylinder radius="0.01" length="0.05"/>
            </geometry>
            <material name="myblue"/>
        </visual>

        <collision>
            <origin xyz="0.0 0.0 0.0" rpy="${pi/2} 0.0 0.0"/>
            <geometry>
                <cylinder radius="0.01" length="0.05"/>
            </geometry>
        </collision>

        <xacro:cylinder_inertia m="0.001" r="0.01" h="0.05"/>
    </link>

    <joint name="steering_connector"  type="fixed">
        <parent link="steering_link"/>
        <child link="connection"/>
        <origin xyz="0.0 0.0 -0.375"/>
    </joint>

    <link name="steering_wheel">
        <visual>
            <origin xyz="0.0 0.0 0.0" rpy="${pi/2} 0.0 0.0"/>
            <geometry>
                <cylinder radius="0.02" length="0.3"/>
            </geometry>
            <material name="black"/>
        </visual>
        
        <collision>
            <origin xyz="0.0 0.0 0.0" rpy="${pi/2} 0.0 0.0"/>
            <geometry>
                <cylinder radius="0.02" length="0.3"/>
            </geometry>
        </collision>

        <xacro:cylinder_inertia m="0.005" r="0.02" h="0.3"/>
    </link>

    <joint name="steering_wheel_connector" type="fixed">
        <parent link="steering_link"/>
        <child link="steering_wheel"/>
        <origin xyz="0.0 0.0 0.4"/>
    </joint>

    <joint name="front_wheel_joint" type="continuous">
        <axis xyz="0 0 1" />
        <parent link="connection"/>
        <child link="front_wheel"/>
        <origin xyz="0.0 -0.05 0.0" rpy="${-pi/2} ${pi/2} 0"/>
        <dynamics damping="0.2" />
    </joint>
    
</robot>