<?xml version="1.0"?>
<robot name="gebot" xmlns:xacro="http://ros.org/wiki/xacro">
    <!-- Material -->
    <material name="black">
        <color rgba="0.0 0.0 0.0 1.0"/>
    </material>
    <material name="white">
        <color rgba="1.0 1.0 1.0 1.0"/>
    </material>
    <material name="wheel">
        <color rgba="0.15 0.15 0.15 1.0"/>
    </material>
    <material name="myblue">
        <color rgba="0.0 0.0 0.5 1.0"/>
    </material>
    <material name="base">
        <color rgba="0.2 0.05 0.05 1.0"/>
    </material>
    <material name="lidar">
        <color rgba="0.8 0.0 0.0 1.0"/>
    </material>

    <!-- Robot Base -->
    <link name="base_link"/>
    
    <!-- Chassis -->
    <link name="base_chassis">
        <collision>
            <origin xyz="0.0 0.0 0.0" rpy="0.0 0.0 0.0" />
            <geometry>
                <box size="1.4 0.8 0.15" />
            </geometry>
        </collision>

        <visual>
            <origin xyz="0.0 0.0 0.0" rpy="0.0 0.0 0.0" />
            <geometry>
                <box size="1.4 0.8 0.15" />
            </geometry>
            <material name="base" />
        </visual>

        <inertial>
            <origin xyz="0 0 0" rpy="0 0 0" />
            <mass value="2" />
            <inertia ixx="0.126164" ixy="0.0" ixz="0.0" iyy="0.416519" iyz="0.0" izz="0.481014" />
        </inertial>
    </link>

    <joint name="chassis_joint" type="fixed">
        <origin xyz="0.5 0.0 0.225" rpy="0.0 0.0 0.0" />
        <parent link="base_link" />
        <child link="base_chassis" />
    </joint>

    <!-- Wheel Links and Joints-->
    <link name="left_wheel">
        <collision>
            <geometry>
                <cylinder length="0.1" radius="0.15" />
            </geometry>
        </collision>
        <visual>
            <geometry>
                <cylinder length="0.1" radius="0.15" />
            </geometry>
            <material name="wheel"/>
        </visual>

        <inertial>
            <mass value="2" />
            <inertia ixx="0.145833" ixy="0.0" ixz="0.0" iyy="0.145833" iyz="0.0" izz="0.125" />
        </inertial>
    </link>

    <joint name="left_wheel_joint" type="continuous">
        <origin xyz="-0.5 0.4 -0.075" rpy="-1.57 0 0" />
        <parent link="base_chassis"/>
        <child link="left_wheel"/>
        <axis xyz="0 0 1" />
        <dynamics damping="0.2" />
    </joint>

    <link name="right_wheel">
        <collision>
            <geometry>
                <cylinder length="0.1" radius="0.15" />
            </geometry>
        </collision>
        <visual>
            <geometry>
                <cylinder length="0.1" radius="0.15" />
            </geometry>
            <material name="wheel"/>
        </visual>

        <inertial>
            <mass value="2" />
            <inertia ixx="0.145833" ixy="0.0" ixz="0.0" iyy="0.145833" iyz="0.0" izz="0.125" />
        </inertial>
    </link>

    <joint name="right_wheel_joint" type="continuous">
        <origin xyz="-0.5 -0.4 -0.075" rpy="-1.57 0 0" />
        <parent link="base_chassis"/>
        <child link="right_wheel"/>
        <axis xyz="0 0 1" />
        <dynamics damping="0.2" />
    </joint>

    <!-- Steering Links and Joints-->
    <link name="steering_link">
        <visual>
            <geometry>
                <cylinder radius="0.02"  length="0.8"/>
            </geometry>
            <material name="white"/>
        </visual>
        <inertial>
            <origin xyz="0 0 0" rpy="0 0 0" />
            <mass value="0.01" />
            <inertia ixx="0.1" ixy="0.0" ixz="0.0" iyy="0.1" iyz="0.0" izz="0.1" />
        </inertial>
    </link>

    <joint name="front_steering_joint" type="revolute">
        <axis xyz="0 0 1"/>
        <limit effort="1000.0" lower="-1.4" upper="1.4" velocity="0.5"/>
        <parent link="base_chassis"/>
        <child link="steering_link"/>
        <origin xyz="0.6 0.05 0.3"/>
    </joint>

    <link name="connection">
        <visual>
            <origin xyz="0.0 0.0 0.0" rpy="${pi/2} 0.0 0.0"/>
            <geometry>
                <cylinder radius="0.01" length="0.05"/>
            </geometry>
            <material name="myblue"/>
        </visual>

        <inertial>
            <origin xyz="0 0 0" rpy="0 0 0" />
            <mass value="0.005" />
            <inertia ixx="0.1" ixy="0.0" ixz="0.0" iyy="0.1" iyz="0.0" izz="0.1" />
        </inertial>
    </link>

    <joint name="steering_connector"  type="fixed">
        <parent link="steering_link"/>
        <child link="connection"/>
        <origin xyz="0.0 0.0 -0.375"/>
    </joint>

    <link name="steering_wheel">
        <visual>
            <origin xyz="0.0 0.0 0.0" rpy="${pi/2} 0.0 0.0"/>
            <geometry>
                <cylinder radius="0.02" length="0.3"/>
            </geometry>
            <material name="black"/>
        </visual>

        <inertial>
            <origin xyz="0 0 0" rpy="0 0 0" />
            <mass value="0.005" />
            <inertia ixx="0.1" ixy="0.0" ixz="0.0" iyy="0.1" iyz="0.0" izz="0.1" />
        </inertial>
    </link>

    <joint name="steering_wheel_connector" type="fixed">
        <parent link="steering_link"/>
        <child link="steering_wheel"/>
        <origin xyz="0.0 0.0 0.4"/>
    </joint>

    <link name="front_wheel">
        <visual>
            <geometry>
                <cylinder length="0.1" radius="0.15" />
            </geometry>
            <material name="wheel"/>
        </visual>
        <collision>
            <geometry>
                <cylinder length="0.1" radius="0.15" />
            </geometry>
        </collision>

        <inertial>
            <origin xyz="0 0 0" rpy="0 0 0" />
            <mass value="15" />
            <inertia ixx="1" ixy="0" ixz="0" iyy="1" iyz="0" izz="1" />
        </inertial>
    </link>

    <joint name="front_wheel_joint" type="continuous">
        <axis xyz="0 0 1" />
        <parent link="connection"/>
        <child link="front_wheel"/>
        <origin xyz="0.0 -0.05 0.0" rpy="${-pi/2} ${pi/2} 0"/>
    </joint>

    <!-- Gazebo Materials -->
    <gazebo reference="base_chassis">
        <material>Gazebo/White</material>
    </gazebo>

    <gazebo reference="base_chassis">
        <material>Gazebo/White</material>
    </gazebo>
    <!-- Wheels -->
    <gazebo reference="right_wheel">
        <material>Gazebo/Grey</material>
        <!--mu1 value="0.001"/-->
        <!--mu2 value="0.001"/-->
    </gazebo>
    <gazebo reference="left_wheel">
        <material>Gazebo/Grey</material>
        <!--mu1 value="0.001"/-->
        <!--mu2 value="0.001"/-->
    </gazebo>
    <gazebo reference="front_wheel">
        <material>Gazebo/Grey</material>
        <!--mu1 value="0.001"/-->
        <!--mu2 value="0.001"/-->
    </gazebo>
    <!-- Steering -->
    <gazebo reference="steering_link">
        <material>Gazebo/White</material>
    </gazebo>
    <gazebo reference="connection">
        <material>Gazebo/Yellow</material>
    </gazebo>
    <gazebo reference="steering_wheel">
        <material>Gazebo/Black</material>
    </gazebo>

    <!-- Ros2_control -->
    <ros2_control name="GazeboSystem" type="system">
        <hardware>
            <plugin>gazebo_ros2_control/GazeboSystem</plugin>
        </hardware>
        <joint name="front_steering_joint">
            <command_interface name="position" />
            <state_interface name="position" />
        </joint>
        <joint name="front_wheel_joint">
            <command_interface name="velocity" />
            <state_interface name="velocity" />
            <state_interface name="position" />
        </joint>
    </ros2_control>
    <gazebo>
        <plugin filename="libgazebo_ros2_control.so" name="gazebo_ros2_control">
            <parameters>$(find my_gebot)/config/tricycle_controller.yaml</parameters>
        </plugin>
    </gazebo>

</robot>